<mujoco model="simplified_humanoid">
    <compiler angle="degree" coordinate="local"/>
    <option timestep="0.01" gravity="0 0 -9.81"/>

    <size njmax="1000" nconmax="200"/>

    <default>
        <joint limited="true" damping="1"/>
        <geom friction="0.8 0.1 0.1" density="1000" margin="0.01" condim="1" rgba="0.8 0.6 0.4 1"/>
        <motor ctrllimited="true" ctrlrange="-1.0 1.0"/>
    </default>

    <worldbody>
        <!-- Ground -->
        <geom name="floor" type="plane" size="10 10 0.1" rgba="0.2 0.3 0.4 1"/>

        <!-- Torso -->
        <body name="torso" pos="0 0 1.0">
            <geom name="torso_geom" type="capsule" size="0.07 0.2" fromto="0 0 0 0 0 0.4" rgba="0.8 0.6 0.6 1"/>
            <joint name="torso_yaw" type="hinge" axis="0 0 1" limited="true" range="-30 30"/>
            <joint name="torso_pitch" type="hinge" axis="1 0 0" limited="true" range="-30 30"/>

            <!-- Left Arm -->
            <body name="left_arm" pos="0 0.15 0.3">
                <joint name="left_shoulder" type="hinge" axis="0 1 0" range="-60 60"/>
                <geom type="capsule" fromto="0 0 0 0 0.2 0" size="0.03"/>
            </body>

            <!-- Right Arm -->
            <body name="right_arm" pos="0 -0.15 0.3">
                <joint name="right_shoulder" type="hinge" axis="0 1 0" range="-60 60"/>
                <geom type="capsule" fromto="0 0 0 0 -0.2 0" size="0.03"/>
            </body>

            <!-- Left Leg -->
            <body name="left_leg" pos="0 0.07 -0.1">
                <joint name="left_hip" type="hinge" axis="1 0 0" range="-45 45"/>
                <geom type="capsule" fromto="0 0 0 -0.3 0 0" size="0.035"/>
                <body name="left_knee" pos="-0.3 0 0">
                    <joint name="left_knee" type="hinge" axis="1 0 0" range="0 90"/>
                    <geom type="capsule" fromto="0 0 0 -0.25 0 0" size="0.03"/>
                </body>
            </body>

            <!-- Right Leg -->
            <body name="right_leg" pos="0 -0.07 -0.1">
                <joint name="right_hip" type="hinge" axis="1 0 0" range="-45 45"/>
                <geom type="capsule" fromto="0 0 0 -0.3 0 0" size="0.035"/>
                <body name="right_knee" pos="-0.3 0 0">
                    <joint name="right_knee" type="hinge" axis="1 0 0" range="0 90"/>
                    <geom type="capsule" fromto="0 0 0 -0.25 0 0" size="0.03"/>
                </body>
            </body>
        </body>
    </worldbody>

    <actuator>
        <motor joint="torso_yaw" ctrlrange="-1 1"/>
        <motor joint="torso_pitch" ctrlrange="-1 1"/>
        <motor joint="left_shoulder" ctrlrange="-1 1"/>
        <motor joint="right_shoulder" ctrlrange="-1 1"/>
        <motor joint="left_hip" ctrlrange="-1 1"/>
        <motor joint="left_knee" ctrlrange="-1 1"/>
        <motor joint="right_hip" ctrlrange="-1 1"/>
        <motor joint="right_knee" ctrlrange="-1 1"/>
    </actuator>
</mujoco>
